Internal Server Error: /profile/1
Traceback (most recent call last):
  File "/Library/Python/2.7/site-packages/django/core/handlers/exception.py", line 39, in inner
    response = get_response(request)
  File "/Library/Python/2.7/site-packages/django/core/handlers/base.py", line 249, in _legacy_get_response
    response = self._get_response(request)
  File "/Library/Python/2.7/site-packages/django/core/handlers/base.py", line 187, in _get_response
    response = self.process_exception_by_middleware(e, request)
  File "/Library/Python/2.7/site-packages/channels/handler.py", line 240, in process_exception_by_middleware
    return super(AsgiHandler, self).process_exception_by_middleware(exception, request)
  File "/Library/Python/2.7/site-packages/django/core/handlers/base.py", line 185, in _get_response
    response = wrapped_callback(request, *callback_args, **callback_kwargs)
  File "/Users/eugenemekhedov/Documents/TFF/School/perconalPage/views.py", line 17, in perconal_page
    user = applyApplication.objects.get(id=user_id)
  File "/Library/Python/2.7/site-packages/django/db/models/manager.py", line 85, in manager_method
    return getattr(self.get_queryset(), name)(*args, **kwargs)
  File "/Library/Python/2.7/site-packages/django/db/models/query.py", line 385, in get
    self.model._meta.object_name
DoesNotExist: applyApplication matching query does not exist.
Not Found: /dogs/
Not Found: /favicon.ico
Internal Server Error: /project/18/
Traceback (most recent call last):
  File "/Library/Python/2.7/site-packages/django/core/handlers/exception.py", line 39, in inner
    response = get_response(request)
  File "/Library/Python/2.7/site-packages/django/core/handlers/base.py", line 249, in _legacy_get_response
    response = self._get_response(request)
  File "/Library/Python/2.7/site-packages/django/core/handlers/base.py", line 187, in _get_response
    response = self.process_exception_by_middleware(e, request)
  File "/Library/Python/2.7/site-packages/channels/handler.py", line 240, in process_exception_by_middleware
    return super(AsgiHandler, self).process_exception_by_middleware(exception, request)
  File "/Library/Python/2.7/site-packages/django/core/handlers/base.py", line 185, in _get_response
    response = wrapped_callback(request, *callback_args, **callback_kwargs)
  File "/Users/eugenemekhedov/Documents/TFF/School/projectsTestsQuestions/views.py", line 70, in projectShow
    return render(request ,'project.html', args)
  File "/Library/Python/2.7/site-packages/django/shortcuts.py", line 30, in render
    content = loader.render_to_string(template_name, context, request, using=using)
  File "/Library/Python/2.7/site-packages/django/template/loader.py", line 68, in render_to_string
    return template.render(context, request)
  File "/Library/Python/2.7/site-packages/django/template/backends/django.py", line 66, in render
    return self.template.render(context)
  File "/Library/Python/2.7/site-packages/django/template/base.py", line 208, in render
    return self._render(context)
  File "/Library/Python/2.7/site-packages/django/template/base.py", line 199, in _render
    return self.nodelist.render(context)
  File "/Library/Python/2.7/site-packages/django/template/base.py", line 994, in render
    bit = node.render_annotated(context)
  File "/Library/Python/2.7/site-packages/django/template/base.py", line 961, in render_annotated
    return self.render(context)
  File "/Library/Python/2.7/site-packages/django/template/loader_tags.py", line 174, in render
    return compiled_parent._render(context)
  File "/Library/Python/2.7/site-packages/django/template/base.py", line 199, in _render
    return self.nodelist.render(context)
  File "/Library/Python/2.7/site-packages/django/template/base.py", line 994, in render
    bit = node.render_annotated(context)
  File "/Library/Python/2.7/site-packages/django/template/base.py", line 961, in render_annotated
    return self.render(context)
  File "/Library/Python/2.7/site-packages/django/template/loader_tags.py", line 70, in render
    result = block.nodelist.render(context)
  File "/Library/Python/2.7/site-packages/django/template/base.py", line 994, in render
    bit = node.render_annotated(context)
  File "/Library/Python/2.7/site-packages/django/template/base.py", line 961, in render_annotated
    return self.render(context)
  File "/Library/Python/2.7/site-packages/django/template/base.py", line 1044, in render
    output = self.filter_expression.resolve(context)
  File "/Library/Python/2.7/site-packages/django/template/base.py", line 711, in resolve
    obj = self.var.resolve(context)
  File "/Library/Python/2.7/site-packages/django/template/base.py", line 852, in resolve
    value = self._resolve_lookup(context)
  File "/Library/Python/2.7/site-packages/django/template/base.py", line 893, in _resolve_lookup
    current = getattr(current, bit)
  File "/Library/Python/2.7/site-packages/django/db/models/fields/files.py", line 68, in _get_url
    self._require_file()
  File "/Library/Python/2.7/site-packages/django/db/models/fields/files.py", line 46, in _require_file
    raise ValueError("The '%s' attribute has no file associated with it." % self.field.name)
ValueError: The 'image' attribute has no file associated with it.
Internal Server Error: /newsproject/
Traceback (most recent call last):
  File "/Library/Python/2.7/site-packages/django/core/handlers/exception.py", line 39, in inner
    response = get_response(request)
  File "/Library/Python/2.7/site-packages/django/core/handlers/base.py", line 249, in _legacy_get_response
    response = self._get_response(request)
  File "/Library/Python/2.7/site-packages/django/core/handlers/base.py", line 187, in _get_response
    response = self.process_exception_by_middleware(e, request)
  File "/Library/Python/2.7/site-packages/channels/handler.py", line 240, in process_exception_by_middleware
    return super(AsgiHandler, self).process_exception_by_middleware(exception, request)
  File "/Library/Python/2.7/site-packages/django/core/handlers/base.py", line 185, in _get_response
    response = wrapped_callback(request, *callback_args, **callback_kwargs)
  File "/Users/eugenemekhedov/Documents/TFF/School/projectsTestsQuestions/views.py", line 83, in newsForCurrentProject
    newsInProject = Project_news.objects.filter(project_id=project.id)
AttributeError: 'NoneType' object has no attribute 'id'
Internal Server Error: /newsproject/
Traceback (most recent call last):
  File "/Library/Python/2.7/site-packages/django/core/handlers/exception.py", line 39, in inner
    response = get_response(request)
  File "/Library/Python/2.7/site-packages/django/core/handlers/base.py", line 249, in _legacy_get_response
    response = self._get_response(request)
  File "/Library/Python/2.7/site-packages/django/core/handlers/base.py", line 187, in _get_response
    response = self.process_exception_by_middleware(e, request)
  File "/Library/Python/2.7/site-packages/channels/handler.py", line 240, in process_exception_by_middleware
    return super(AsgiHandler, self).process_exception_by_middleware(exception, request)
  File "/Library/Python/2.7/site-packages/django/core/handlers/base.py", line 185, in _get_response
    response = wrapped_callback(request, *callback_args, **callback_kwargs)
  File "/Users/eugenemekhedov/Documents/TFF/School/projectsTestsQuestions/views.py", line 83, in newsForCurrentProject
    newsInProject = Project_news.objects.filter(project_id=project.id)
AttributeError: 'NoneType' object has no attribute 'id'
Internal Server Error: /aboutus/
Traceback (most recent call last):
  File "/Library/Python/2.7/site-packages/django/core/handlers/exception.py", line 39, in inner
    response = get_response(request)
  File "/Library/Python/2.7/site-packages/django/core/handlers/base.py", line 249, in _legacy_get_response
    response = self._get_response(request)
  File "/Library/Python/2.7/site-packages/django/core/handlers/base.py", line 187, in _get_response
    response = self.process_exception_by_middleware(e, request)
  File "/Library/Python/2.7/site-packages/channels/handler.py", line 240, in process_exception_by_middleware
    return super(AsgiHandler, self).process_exception_by_middleware(exception, request)
  File "/Library/Python/2.7/site-packages/django/core/handlers/base.py", line 185, in _get_response
    response = wrapped_callback(request, *callback_args, **callback_kwargs)
  File "/Users/eugenemekhedov/Documents/TFF/School/aboutus/views.py", line 14, in aboutUs
    return render(request ,'aboutus.html', args)
  File "/Library/Python/2.7/site-packages/django/shortcuts.py", line 30, in render
    content = loader.render_to_string(template_name, context, request, using=using)
  File "/Library/Python/2.7/site-packages/django/template/loader.py", line 68, in render_to_string
    return template.render(context, request)
  File "/Library/Python/2.7/site-packages/django/template/backends/django.py", line 66, in render
    return self.template.render(context)
  File "/Library/Python/2.7/site-packages/django/template/base.py", line 208, in render
    return self._render(context)
  File "/Library/Python/2.7/site-packages/django/template/base.py", line 199, in _render
    return self.nodelist.render(context)
  File "/Library/Python/2.7/site-packages/django/template/base.py", line 994, in render
    bit = node.render_annotated(context)
  File "/Library/Python/2.7/site-packages/django/template/base.py", line 961, in render_annotated
    return self.render(context)
  File "/Library/Python/2.7/site-packages/django/template/loader_tags.py", line 174, in render
    return compiled_parent._render(context)
  File "/Library/Python/2.7/site-packages/django/template/base.py", line 199, in _render
    return self.nodelist.render(context)
  File "/Library/Python/2.7/site-packages/django/template/base.py", line 994, in render
    bit = node.render_annotated(context)
  File "/Library/Python/2.7/site-packages/django/template/base.py", line 961, in render_annotated
    return self.render(context)
  File "/Library/Python/2.7/site-packages/django/template/loader_tags.py", line 70, in render
    result = block.nodelist.render(context)
  File "/Library/Python/2.7/site-packages/django/template/base.py", line 994, in render
    bit = node.render_annotated(context)
  File "/Library/Python/2.7/site-packages/django/template/base.py", line 961, in render_annotated
    return self.render(context)
  File "/Library/Python/2.7/site-packages/django/template/base.py", line 1044, in render
    output = self.filter_expression.resolve(context)
  File "/Library/Python/2.7/site-packages/django/template/base.py", line 711, in resolve
    obj = self.var.resolve(context)
  File "/Library/Python/2.7/site-packages/django/template/base.py", line 852, in resolve
    value = self._resolve_lookup(context)
  File "/Library/Python/2.7/site-packages/django/template/base.py", line 893, in _resolve_lookup
    current = getattr(current, bit)
  File "/Library/Python/2.7/site-packages/django/db/models/fields/files.py", line 68, in _get_url
    self._require_file()
  File "/Library/Python/2.7/site-packages/django/db/models/fields/files.py", line 46, in _require_file
    raise ValueError("The '%s' attribute has no file associated with it." % self.field.name)
ValueError: The 'image' attribute has no file associated with it.
Internal Server Error: /page/0/
Traceback (most recent call last):
  File "/Library/Python/2.7/site-packages/django/core/handlers/exception.py", line 39, in inner
    response = get_response(request)
  File "/Library/Python/2.7/site-packages/django/core/handlers/base.py", line 249, in _legacy_get_response
    response = self._get_response(request)
  File "/Library/Python/2.7/site-packages/django/core/handlers/base.py", line 187, in _get_response
    response = self.process_exception_by_middleware(e, request)
  File "/Library/Python/2.7/site-packages/channels/handler.py", line 240, in process_exception_by_middleware
    return super(AsgiHandler, self).process_exception_by_middleware(exception, request)
  File "/Library/Python/2.7/site-packages/django/core/handlers/base.py", line 185, in _get_response
    response = wrapped_callback(request, *callback_args, **callback_kwargs)
  File "/Users/eugenemekhedov/Documents/TFF/School/School/views.py", line 38, in mainTwo
    news = news_Paragraph.objects.order_by('id')[(int(page)-1)*4:int(page)*4]
  File "/Library/Python/2.7/site-packages/django/db/models/query.py", line 275, in __getitem__
    "Negative indexing is not supported."
AssertionError: Negative indexing is not supported.
Not Found: /accounts/login/
Internal Server Error: /admin/apply/applyapplication/
Traceback (most recent call last):
  File "/Library/Python/2.7/site-packages/django/core/handlers/exception.py", line 39, in inner
    response = get_response(request)
  File "/Library/Python/2.7/site-packages/django/core/handlers/base.py", line 249, in _legacy_get_response
    response = self._get_response(request)
  File "/Library/Python/2.7/site-packages/django/core/handlers/base.py", line 187, in _get_response
    response = self.process_exception_by_middleware(e, request)
  File "/Library/Python/2.7/site-packages/channels/handler.py", line 240, in process_exception_by_middleware
    return super(AsgiHandler, self).process_exception_by_middleware(exception, request)
  File "/Library/Python/2.7/site-packages/django/core/handlers/base.py", line 185, in _get_response
    response = wrapped_callback(request, *callback_args, **callback_kwargs)
  File "/Library/Python/2.7/site-packages/django/contrib/admin/options.py", line 544, in wrapper
    return self.admin_site.admin_view(view)(*args, **kwargs)
  File "/Library/Python/2.7/site-packages/django/utils/decorators.py", line 149, in _wrapped_view
    response = view_func(request, *args, **kwargs)
  File "/Library/Python/2.7/site-packages/django/views/decorators/cache.py", line 57, in _wrapped_view_func
    response = view_func(request, *args, **kwargs)
  File "/Library/Python/2.7/site-packages/django/contrib/admin/sites.py", line 211, in inner
    return view(request, *args, **kwargs)
  File "/Library/Python/2.7/site-packages/django/utils/decorators.py", line 67, in _wrapper
    return bound_func(*args, **kwargs)
  File "/Library/Python/2.7/site-packages/django/utils/decorators.py", line 149, in _wrapped_view
    response = view_func(request, *args, **kwargs)
  File "/Library/Python/2.7/site-packages/django/utils/decorators.py", line 63, in bound_func
    return func.__get__(self, type(self))(*args2, **kwargs2)
  File "/Library/Python/2.7/site-packages/django/contrib/admin/options.py", line 1569, in changelist_view
    response = self.response_action(request, queryset=cl.get_queryset(request))
  File "/Library/Python/2.7/site-packages/django/contrib/admin/options.py", line 1305, in response_action
    response = func(self, request, queryset)
  File "/Users/eugenemekhedov/Documents/TFF/School/apply/admin.py", line 403, in distribution_of_participants_best
    registerUsers(member, project)
  File "/Users/eugenemekhedov/Documents/TFF/School/apply/admin.py", line 436, in registerUsers
    password=passForNewUser)
  File "/Library/Python/2.7/site-packages/django/contrib/auth/models.py", line 157, in create_user
    return self._create_user(username, email, password, **extra_fields)
  File "/Library/Python/2.7/site-packages/django/contrib/auth/models.py", line 151, in _create_user
    user.save(using=self._db)
  File "/Library/Python/2.7/site-packages/django/contrib/auth/base_user.py", line 80, in save
    super(AbstractBaseUser, self).save(*args, **kwargs)
  File "/Library/Python/2.7/site-packages/django/db/models/base.py", line 796, in save
    force_update=force_update, update_fields=update_fields)
  File "/Library/Python/2.7/site-packages/django/db/models/base.py", line 824, in save_base
    updated = self._save_table(raw, cls, force_insert, force_update, using, update_fields)
  File "/Library/Python/2.7/site-packages/django/db/models/base.py", line 908, in _save_table
    result = self._do_insert(cls._base_manager, using, fields, update_pk, raw)
  File "/Library/Python/2.7/site-packages/django/db/models/base.py", line 947, in _do_insert
    using=using, raw=raw)
  File "/Library/Python/2.7/site-packages/django/db/models/manager.py", line 85, in manager_method
    return getattr(self.get_queryset(), name)(*args, **kwargs)
  File "/Library/Python/2.7/site-packages/django/db/models/query.py", line 1043, in _insert
    return query.get_compiler(using=using).execute_sql(return_id)
  File "/Library/Python/2.7/site-packages/django/db/models/sql/compiler.py", line 1054, in execute_sql
    cursor.execute(sql, params)
  File "/Library/Python/2.7/site-packages/django/db/backends/utils.py", line 79, in execute
    return super(CursorDebugWrapper, self).execute(sql, params)
  File "/Library/Python/2.7/site-packages/django/db/backends/utils.py", line 64, in execute
    return self.cursor.execute(sql, params)
  File "/Library/Python/2.7/site-packages/django/db/utils.py", line 94, in __exit__
    six.reraise(dj_exc_type, dj_exc_value, traceback)
  File "/Library/Python/2.7/site-packages/django/db/backends/utils.py", line 64, in execute
    return self.cursor.execute(sql, params)
  File "/Library/Python/2.7/site-packages/django/db/backends/mysql/base.py", line 112, in execute
    return self.cursor.execute(query, args)
  File "/Library/Python/2.7/site-packages/MySQLdb/cursors.py", line 205, in execute
    self.errorhandler(self, exc, value)
  File "/Library/Python/2.7/site-packages/MySQLdb/connections.py", line 36, in defaulterrorhandler
    raise errorclass, errorvalue
IntegrityError: (1062, "Duplicate entry 'Artem' for key 'username'")
Internal Server Error: /admin/apply/applyapplication/
Traceback (most recent call last):
  File "/Library/Python/2.7/site-packages/django/core/handlers/exception.py", line 39, in inner
    response = get_response(request)
  File "/Library/Python/2.7/site-packages/django/core/handlers/base.py", line 249, in _legacy_get_response
    response = self._get_response(request)
  File "/Library/Python/2.7/site-packages/django/core/handlers/base.py", line 187, in _get_response
    response = self.process_exception_by_middleware(e, request)
  File "/Library/Python/2.7/site-packages/channels/handler.py", line 240, in process_exception_by_middleware
    return super(AsgiHandler, self).process_exception_by_middleware(exception, request)
  File "/Library/Python/2.7/site-packages/django/core/handlers/base.py", line 185, in _get_response
    response = wrapped_callback(request, *callback_args, **callback_kwargs)
  File "/Library/Python/2.7/site-packages/django/contrib/admin/options.py", line 544, in wrapper
    return self.admin_site.admin_view(view)(*args, **kwargs)
  File "/Library/Python/2.7/site-packages/django/utils/decorators.py", line 149, in _wrapped_view
    response = view_func(request, *args, **kwargs)
  File "/Library/Python/2.7/site-packages/django/views/decorators/cache.py", line 57, in _wrapped_view_func
    response = view_func(request, *args, **kwargs)
  File "/Library/Python/2.7/site-packages/django/contrib/admin/sites.py", line 211, in inner
    return view(request, *args, **kwargs)
  File "/Library/Python/2.7/site-packages/django/utils/decorators.py", line 67, in _wrapper
    return bound_func(*args, **kwargs)
  File "/Library/Python/2.7/site-packages/django/utils/decorators.py", line 149, in _wrapped_view
    response = view_func(request, *args, **kwargs)
  File "/Library/Python/2.7/site-packages/django/utils/decorators.py", line 63, in bound_func
    return func.__get__(self, type(self))(*args2, **kwargs2)
  File "/Library/Python/2.7/site-packages/django/contrib/admin/options.py", line 1569, in changelist_view
    response = self.response_action(request, queryset=cl.get_queryset(request))
  File "/Library/Python/2.7/site-packages/django/contrib/admin/options.py", line 1305, in response_action
    response = func(self, request, queryset)
  File "/Users/eugenemekhedov/Documents/TFF/School/apply/admin.py", line 403, in distribution_of_participants_best
    registerUsers(member, project)
  File "/Users/eugenemekhedov/Documents/TFF/School/apply/admin.py", line 436, in registerUsers
    password=passForNewUser)
  File "/Library/Python/2.7/site-packages/django/contrib/auth/models.py", line 157, in create_user
    return self._create_user(username, email, password, **extra_fields)
  File "/Library/Python/2.7/site-packages/django/contrib/auth/models.py", line 151, in _create_user
    user.save(using=self._db)
  File "/Library/Python/2.7/site-packages/django/contrib/auth/base_user.py", line 80, in save
    super(AbstractBaseUser, self).save(*args, **kwargs)
  File "/Library/Python/2.7/site-packages/django/db/models/base.py", line 796, in save
    force_update=force_update, update_fields=update_fields)
  File "/Library/Python/2.7/site-packages/django/db/models/base.py", line 824, in save_base
    updated = self._save_table(raw, cls, force_insert, force_update, using, update_fields)
  File "/Library/Python/2.7/site-packages/django/db/models/base.py", line 908, in _save_table
    result = self._do_insert(cls._base_manager, using, fields, update_pk, raw)
  File "/Library/Python/2.7/site-packages/django/db/models/base.py", line 947, in _do_insert
    using=using, raw=raw)
  File "/Library/Python/2.7/site-packages/django/db/models/manager.py", line 85, in manager_method
    return getattr(self.get_queryset(), name)(*args, **kwargs)
  File "/Library/Python/2.7/site-packages/django/db/models/query.py", line 1043, in _insert
    return query.get_compiler(using=using).execute_sql(return_id)
  File "/Library/Python/2.7/site-packages/django/db/models/sql/compiler.py", line 1054, in execute_sql
    cursor.execute(sql, params)
  File "/Library/Python/2.7/site-packages/django/db/backends/utils.py", line 79, in execute
    return super(CursorDebugWrapper, self).execute(sql, params)
  File "/Library/Python/2.7/site-packages/django/db/backends/utils.py", line 64, in execute
    return self.cursor.execute(sql, params)
  File "/Library/Python/2.7/site-packages/django/db/utils.py", line 94, in __exit__
    six.reraise(dj_exc_type, dj_exc_value, traceback)
  File "/Library/Python/2.7/site-packages/django/db/backends/utils.py", line 64, in execute
    return self.cursor.execute(sql, params)
  File "/Library/Python/2.7/site-packages/django/db/backends/mysql/base.py", line 112, in execute
    return self.cursor.execute(query, args)
  File "/Library/Python/2.7/site-packages/MySQLdb/cursors.py", line 205, in execute
    self.errorhandler(self, exc, value)
  File "/Library/Python/2.7/site-packages/MySQLdb/connections.py", line 36, in defaulterrorhandler
    raise errorclass, errorvalue
IntegrityError: (1062, "Duplicate entry 'Elizaveta' for key 'username'")
Internal Server Error: /chat/room/96/
Traceback (most recent call last):
  File "/Library/Python/2.7/site-packages/django/core/handlers/exception.py", line 39, in inner
    response = get_response(request)
  File "/Library/Python/2.7/site-packages/django/core/handlers/base.py", line 249, in _legacy_get_response
    response = self._get_response(request)
  File "/Library/Python/2.7/site-packages/django/core/handlers/base.py", line 187, in _get_response
    response = self.process_exception_by_middleware(e, request)
  File "/Library/Python/2.7/site-packages/channels/handler.py", line 240, in process_exception_by_middleware
    return super(AsgiHandler, self).process_exception_by_middleware(exception, request)
  File "/Library/Python/2.7/site-packages/django/core/handlers/base.py", line 185, in _get_response
    response = wrapped_callback(request, *callback_args, **callback_kwargs)
  File "/Library/Python/2.7/site-packages/django/contrib/auth/decorators.py", line 23, in _wrapped_view
    return view_func(request, *args, **kwargs)
  File "/Users/eugenemekhedov/Documents/TFF/School/chat/views.py", line 82, in chatRoom
    args["sender"] = applyApplication.objects.get(id=member.id)
  File "/Library/Python/2.7/site-packages/django/db/models/manager.py", line 85, in manager_method
    return getattr(self.get_queryset(), name)(*args, **kwargs)
  File "/Library/Python/2.7/site-packages/django/db/models/query.py", line 385, in get
    self.model._meta.object_name
DoesNotExist: applyApplication matching query does not exist.
Internal Server Error: /chat/room/79/
Traceback (most recent call last):
  File "/Library/Python/2.7/site-packages/django/core/handlers/exception.py", line 39, in inner
    response = get_response(request)
  File "/Library/Python/2.7/site-packages/django/core/handlers/base.py", line 249, in _legacy_get_response
    response = self._get_response(request)
  File "/Library/Python/2.7/site-packages/django/core/handlers/base.py", line 187, in _get_response
    response = self.process_exception_by_middleware(e, request)
  File "/Library/Python/2.7/site-packages/channels/handler.py", line 240, in process_exception_by_middleware
    return super(AsgiHandler, self).process_exception_by_middleware(exception, request)
  File "/Library/Python/2.7/site-packages/django/core/handlers/base.py", line 185, in _get_response
    response = wrapped_callback(request, *callback_args, **callback_kwargs)
  File "/Library/Python/2.7/site-packages/django/contrib/auth/decorators.py", line 23, in _wrapped_view
    return view_func(request, *args, **kwargs)
  File "/Users/eugenemekhedov/Documents/TFF/School/chat/views.py", line 82, in chatRoom
    args["sender"] = applyApplication.objects.get(id=member.id)
  File "/Library/Python/2.7/site-packages/django/db/models/manager.py", line 85, in manager_method
    return getattr(self.get_queryset(), name)(*args, **kwargs)
  File "/Library/Python/2.7/site-packages/django/db/models/query.py", line 385, in get
    self.model._meta.object_name
DoesNotExist: applyApplication matching query does not exist.
Internal Server Error: /api/chat/rooms/
Traceback (most recent call last):
  File "/Library/Python/2.7/site-packages/django/core/handlers/exception.py", line 39, in inner
    response = get_response(request)
  File "/Library/Python/2.7/site-packages/django/core/handlers/base.py", line 249, in _legacy_get_response
    response = self._get_response(request)
  File "/Library/Python/2.7/site-packages/django/core/handlers/base.py", line 187, in _get_response
    response = self.process_exception_by_middleware(e, request)
  File "/Library/Python/2.7/site-packages/channels/handler.py", line 240, in process_exception_by_middleware
    return super(AsgiHandler, self).process_exception_by_middleware(exception, request)
  File "/Library/Python/2.7/site-packages/django/core/handlers/base.py", line 185, in _get_response
    response = wrapped_callback(request, *callback_args, **callback_kwargs)
  File "/Library/Python/2.7/site-packages/django/views/decorators/csrf.py", line 58, in wrapped_view
    return view_func(*args, **kwargs)
  File "/Library/Python/2.7/site-packages/django/views/generic/base.py", line 68, in view
    return self.dispatch(request, *args, **kwargs)
  File "/Library/Python/2.7/site-packages/rest_framework/views.py", line 483, in dispatch
    response = self.handle_exception(exc)
  File "/Library/Python/2.7/site-packages/rest_framework/views.py", line 443, in handle_exception
    self.raise_uncaught_exception(exc)
  File "/Library/Python/2.7/site-packages/rest_framework/views.py", line 480, in dispatch
    response = handler(request, *args, **kwargs)
  File "/Library/Python/2.7/site-packages/rest_framework/generics.py", line 240, in get
    return self.list(request, *args, **kwargs)
  File "/Library/Python/2.7/site-packages/rest_framework/mixins.py", line 48, in list
    return Response(serializer.data)
  File "/Library/Python/2.7/site-packages/rest_framework/serializers.py", line 729, in data
    ret = super(ListSerializer, self).data
  File "/Library/Python/2.7/site-packages/rest_framework/serializers.py", line 262, in data
    self._data = self.to_representation(self.instance)
  File "/Library/Python/2.7/site-packages/rest_framework/serializers.py", line 647, in to_representation
    self.child.to_representation(item) for item in iterable
  File "/Library/Python/2.7/site-packages/rest_framework/serializers.py", line 500, in to_representation
    ret[field.field_name] = field.to_representation(attribute)
  File "/Library/Python/2.7/site-packages/rest_framework/serializers.py", line 487, in to_representation
    attribute = field.get_attribute(instance)
  File "/Library/Python/2.7/site-packages/rest_framework/fields.py", line 463, in get_attribute
    raise type(exc)(msg)
AttributeError: Got AttributeError when attempting to get a value for field `surname` on serializer `UserProfileSerializer`.
The serializer field might be named incorrectly and not match any attribute or key on the `ManyRelatedManager` instance.
Original exception text was: 'ManyRelatedManager' object has no attribute 'surname'.
Internal Server Error: /api/chat/rooms/
Traceback (most recent call last):
  File "/Library/Python/2.7/site-packages/django/core/handlers/exception.py", line 39, in inner
    response = get_response(request)
  File "/Library/Python/2.7/site-packages/django/core/handlers/base.py", line 249, in _legacy_get_response
    response = self._get_response(request)
  File "/Library/Python/2.7/site-packages/django/core/handlers/base.py", line 187, in _get_response
    response = self.process_exception_by_middleware(e, request)
  File "/Library/Python/2.7/site-packages/channels/handler.py", line 240, in process_exception_by_middleware
    return super(AsgiHandler, self).process_exception_by_middleware(exception, request)
  File "/Library/Python/2.7/site-packages/django/core/handlers/base.py", line 185, in _get_response
    response = wrapped_callback(request, *callback_args, **callback_kwargs)
  File "/Library/Python/2.7/site-packages/django/views/decorators/csrf.py", line 58, in wrapped_view
    return view_func(*args, **kwargs)
  File "/Library/Python/2.7/site-packages/django/views/generic/base.py", line 68, in view
    return self.dispatch(request, *args, **kwargs)
  File "/Library/Python/2.7/site-packages/rest_framework/views.py", line 483, in dispatch
    response = self.handle_exception(exc)
  File "/Library/Python/2.7/site-packages/rest_framework/views.py", line 443, in handle_exception
    self.raise_uncaught_exception(exc)
  File "/Library/Python/2.7/site-packages/rest_framework/views.py", line 480, in dispatch
    response = handler(request, *args, **kwargs)
  File "/Library/Python/2.7/site-packages/rest_framework/generics.py", line 240, in get
    return self.list(request, *args, **kwargs)
  File "/Library/Python/2.7/site-packages/rest_framework/mixins.py", line 48, in list
    return Response(serializer.data)
  File "/Library/Python/2.7/site-packages/rest_framework/serializers.py", line 729, in data
    ret = super(ListSerializer, self).data
  File "/Library/Python/2.7/site-packages/rest_framework/serializers.py", line 262, in data
    self._data = self.to_representation(self.instance)
  File "/Library/Python/2.7/site-packages/rest_framework/serializers.py", line 647, in to_representation
    self.child.to_representation(item) for item in iterable
  File "/Library/Python/2.7/site-packages/rest_framework/serializers.py", line 500, in to_representation
    ret[field.field_name] = field.to_representation(attribute)
  File "/Library/Python/2.7/site-packages/rest_framework/serializers.py", line 487, in to_representation
    attribute = field.get_attribute(instance)
  File "/Library/Python/2.7/site-packages/rest_framework/fields.py", line 463, in get_attribute
    raise type(exc)(msg)
AttributeError: Got AttributeError when attempting to get a value for field `surname` on serializer `UserProfileSerializer`.
The serializer field might be named incorrectly and not match any attribute or key on the `ManyRelatedManager` instance.
Original exception text was: 'ManyRelatedManager' object has no attribute 'surname'.
Internal Server Error: /profile/1
Traceback (most recent call last):
  File "/Library/Python/2.7/site-packages/django/core/handlers/exception.py", line 39, in inner
    response = get_response(request)
  File "/Library/Python/2.7/site-packages/django/core/handlers/base.py", line 249, in _legacy_get_response
    response = self._get_response(request)
  File "/Library/Python/2.7/site-packages/django/core/handlers/base.py", line 187, in _get_response
    response = self.process_exception_by_middleware(e, request)
  File "/Library/Python/2.7/site-packages/channels/handler.py", line 240, in process_exception_by_middleware
    return super(AsgiHandler, self).process_exception_by_middleware(exception, request)
  File "/Library/Python/2.7/site-packages/django/core/handlers/base.py", line 185, in _get_response
    response = wrapped_callback(request, *callback_args, **callback_kwargs)
  File "/Users/eugenemekhedov/Documents/TFF/School/perconalPage/views.py", line 17, in perconal_page
    user = applyApplication.objects.get(id=user_id)
  File "/Library/Python/2.7/site-packages/django/db/models/manager.py", line 85, in manager_method
    return getattr(self.get_queryset(), name)(*args, **kwargs)
  File "/Library/Python/2.7/site-packages/django/db/models/query.py", line 385, in get
    self.model._meta.object_name
DoesNotExist: applyApplication matching query does not exist.
Not Found: /favicon.ico
Internal Server Error: /pdf/
Traceback (most recent call last):
  File "/Library/Python/2.7/site-packages/django/core/handlers/exception.py", line 39, in inner
    response = get_response(request)
  File "/Library/Python/2.7/site-packages/django/core/handlers/base.py", line 249, in _legacy_get_response
    response = self._get_response(request)
  File "/Library/Python/2.7/site-packages/django/core/handlers/base.py", line 187, in _get_response
    response = self.process_exception_by_middleware(e, request)
  File "/Library/Python/2.7/site-packages/channels/handler.py", line 240, in process_exception_by_middleware
    return super(AsgiHandler, self).process_exception_by_middleware(exception, request)
  File "/Library/Python/2.7/site-packages/django/core/handlers/base.py", line 185, in _get_response
    response = wrapped_callback(request, *callback_args, **callback_kwargs)
  File "/Users/eugenemekhedov/Documents/TFF/School/School/views.py", line 107, in pdf
    'args': results,
  File "/Users/eugenemekhedov/Documents/TFF/School/School/views.py", line 94, in render_to_pdf
    pdf = pisa.pisaDocument(StringIO.StringIO(html.encode("ISO-8859-1")), result)
  File "/Library/Python/2.7/site-packages/django/utils/functional.py", line 15, in _curried
    return _curried_func(*(args + moreargs), **dict(kwargs, **morekwargs))
  File "/Library/Python/2.7/site-packages/django/utils/safestring.py", line 104, in _proxy_method
    data = method(self, *args, **kwargs)
UnicodeEncodeError: 'latin-1' codec can't encode characters in position 247-250: ordinal not in range(256)
Internal Server Error: /pdf/
Traceback (most recent call last):
  File "/Library/Python/2.7/site-packages/django/core/handlers/exception.py", line 39, in inner
    response = get_response(request)
  File "/Library/Python/2.7/site-packages/django/core/handlers/base.py", line 249, in _legacy_get_response
    response = self._get_response(request)
  File "/Library/Python/2.7/site-packages/django/core/handlers/base.py", line 187, in _get_response
    response = self.process_exception_by_middleware(e, request)
  File "/Library/Python/2.7/site-packages/channels/handler.py", line 240, in process_exception_by_middleware
    return super(AsgiHandler, self).process_exception_by_middleware(exception, request)
  File "/Library/Python/2.7/site-packages/django/core/handlers/base.py", line 185, in _get_response
    response = wrapped_callback(request, *callback_args, **callback_kwargs)
  File "/Users/eugenemekhedov/Documents/TFF/School/School/views.py", line 107, in pdf
    'args': results,
  File "/Users/eugenemekhedov/Documents/TFF/School/School/views.py", line 94, in render_to_pdf
    pdf = pisa.pisaDocument(StringIO.StringIO(html.encode("ISO-8859-1")), result)
  File "/Library/Python/2.7/site-packages/xhtml2pdf-0.2b1-py2.7.egg/xhtml2pdf/document.py", line 97, in pisaDocument
    encoding, context=context, xml_output=xml_output)
  File "/Library/Python/2.7/site-packages/xhtml2pdf-0.2b1-py2.7.egg/xhtml2pdf/document.py", line 59, in pisaStory
    pisaParser(src, context, default_css, xhtml, encoding, xml_output)
  File "/Library/Python/2.7/site-packages/xhtml2pdf-0.2b1-py2.7.egg/xhtml2pdf/parser.py", line 708, in pisaParser
    pisaLoop(document, context)
  File "/Library/Python/2.7/site-packages/xhtml2pdf-0.2b1-py2.7.egg/xhtml2pdf/parser.py", line 648, in pisaLoop
    pisaLoop(node, context, path, **kw)
  File "/Library/Python/2.7/site-packages/xhtml2pdf-0.2b1-py2.7.egg/xhtml2pdf/parser.py", line 593, in pisaLoop
    pisaLoop(nnode, context, path, **kw)
  File "/Library/Python/2.7/site-packages/xhtml2pdf-0.2b1-py2.7.egg/xhtml2pdf/parser.py", line 593, in pisaLoop
    pisaLoop(nnode, context, path, **kw)
  File "/Library/Python/2.7/site-packages/xhtml2pdf-0.2b1-py2.7.egg/xhtml2pdf/parser.py", line 593, in pisaLoop
    pisaLoop(nnode, context, path, **kw)
  File "/Library/Python/2.7/site-packages/xhtml2pdf-0.2b1-py2.7.egg/xhtml2pdf/parser.py", line 593, in pisaLoop
    pisaLoop(nnode, context, path, **kw)
  File "/Library/Python/2.7/site-packages/xhtml2pdf-0.2b1-py2.7.egg/xhtml2pdf/parser.py", line 537, in pisaLoop
    CSS2Frag(context, kw, isBlock)
  File "/Library/Python/2.7/site-packages/xhtml2pdf-0.2b1-py2.7.egg/xhtml2pdf/parser.py", line 279, in CSS2Frag
    c.frag.backColor = getColor(c.cssAttr["background-color"])
  File "/Library/Python/2.7/site-packages/xhtml2pdf-0.2b1-py2.7.egg/xhtml2pdf/util.py", line 98, in __call__
    res = self.func(*args, **kwargs)
  File "/Library/Python/2.7/site-packages/xhtml2pdf-0.2b1-py2.7.egg/xhtml2pdf/util.py", line 152, in getColor
    return toColor(value, default)  # Calling the reportlab function
  File "/Library/Python/2.7/site-packages/reportlab/lib/colors.py", line 870, in __call__
    raise ValueError('Invalid color value %r' % arg)
ValueError: Invalid color value 'media/certificate/certificate.png'
Not Found: /messages/inbox/
Internal Server Error: /pdf/
Traceback (most recent call last):
  File "/Library/Python/2.7/site-packages/django/core/handlers/exception.py", line 39, in inner
    response = get_response(request)
  File "/Library/Python/2.7/site-packages/django/core/handlers/base.py", line 249, in _legacy_get_response
    response = self._get_response(request)
  File "/Library/Python/2.7/site-packages/django/core/handlers/base.py", line 187, in _get_response
    response = self.process_exception_by_middleware(e, request)
  File "/Library/Python/2.7/site-packages/channels/handler.py", line 240, in process_exception_by_middleware
    return super(AsgiHandler, self).process_exception_by_middleware(exception, request)
  File "/Library/Python/2.7/site-packages/django/core/handlers/base.py", line 185, in _get_response
    response = wrapped_callback(request, *callback_args, **callback_kwargs)
  File "/Users/eugenemekhedov/Documents/TFF/School/School/views.py", line 107, in pdf
    'results': results,
  File "/Users/eugenemekhedov/Documents/TFF/School/School/views.py", line 94, in render_to_pdf
    pdf = pisa.pisaDocument(StringIO.StringIO(html.encode("ISO-8859-1")), result)
  File "/Library/Python/2.7/site-packages/xhtml2pdf-0.2b1-py2.7.egg/xhtml2pdf/document.py", line 97, in pisaDocument
    encoding, context=context, xml_output=xml_output)
  File "/Library/Python/2.7/site-packages/xhtml2pdf-0.2b1-py2.7.egg/xhtml2pdf/document.py", line 59, in pisaStory
    pisaParser(src, context, default_css, xhtml, encoding, xml_output)
  File "/Library/Python/2.7/site-packages/xhtml2pdf-0.2b1-py2.7.egg/xhtml2pdf/parser.py", line 708, in pisaParser
    pisaLoop(document, context)
  File "/Library/Python/2.7/site-packages/xhtml2pdf-0.2b1-py2.7.egg/xhtml2pdf/parser.py", line 648, in pisaLoop
    pisaLoop(node, context, path, **kw)
  File "/Library/Python/2.7/site-packages/xhtml2pdf-0.2b1-py2.7.egg/xhtml2pdf/parser.py", line 593, in pisaLoop
    pisaLoop(nnode, context, path, **kw)
  File "/Library/Python/2.7/site-packages/xhtml2pdf-0.2b1-py2.7.egg/xhtml2pdf/parser.py", line 593, in pisaLoop
    pisaLoop(nnode, context, path, **kw)
  File "/Library/Python/2.7/site-packages/xhtml2pdf-0.2b1-py2.7.egg/xhtml2pdf/parser.py", line 593, in pisaLoop
    pisaLoop(nnode, context, path, **kw)
  File "/Library/Python/2.7/site-packages/xhtml2pdf-0.2b1-py2.7.egg/xhtml2pdf/parser.py", line 537, in pisaLoop
    CSS2Frag(context, kw, isBlock)
  File "/Library/Python/2.7/site-packages/xhtml2pdf-0.2b1-py2.7.egg/xhtml2pdf/parser.py", line 279, in CSS2Frag
    c.frag.backColor = getColor(c.cssAttr["background-color"])
  File "/Library/Python/2.7/site-packages/xhtml2pdf-0.2b1-py2.7.egg/xhtml2pdf/util.py", line 98, in __call__
    res = self.func(*args, **kwargs)
  File "/Library/Python/2.7/site-packages/xhtml2pdf-0.2b1-py2.7.egg/xhtml2pdf/util.py", line 152, in getColor
    return toColor(value, default)  # Calling the reportlab function
  File "/Library/Python/2.7/site-packages/reportlab/lib/colors.py", line 870, in __call__
    raise ValueError('Invalid color value %r' % arg)
ValueError: Invalid color value '/media/certificate/certificate.png'
Internal Server Error: /pdf/
Traceback (most recent call last):
  File "/Library/Python/2.7/site-packages/django/core/handlers/exception.py", line 39, in inner
    response = get_response(request)
  File "/Library/Python/2.7/site-packages/django/core/handlers/base.py", line 249, in _legacy_get_response
    response = self._get_response(request)
  File "/Library/Python/2.7/site-packages/django/core/handlers/base.py", line 187, in _get_response
    response = self.process_exception_by_middleware(e, request)
  File "/Library/Python/2.7/site-packages/channels/handler.py", line 240, in process_exception_by_middleware
    return super(AsgiHandler, self).process_exception_by_middleware(exception, request)
  File "/Library/Python/2.7/site-packages/django/core/handlers/base.py", line 185, in _get_response
    response = wrapped_callback(request, *callback_args, **callback_kwargs)
  File "/Users/eugenemekhedov/Documents/TFF/School/School/views.py", line 107, in pdf
    'results': results,
  File "/Users/eugenemekhedov/Documents/TFF/School/School/views.py", line 94, in render_to_pdf
    pdf = pisa.pisaDocument(StringIO.StringIO(html.encode("ISO-8859-1")), result)
  File "/Library/Python/2.7/site-packages/xhtml2pdf-0.2b1-py2.7.egg/xhtml2pdf/document.py", line 97, in pisaDocument
    encoding, context=context, xml_output=xml_output)
  File "/Library/Python/2.7/site-packages/xhtml2pdf-0.2b1-py2.7.egg/xhtml2pdf/document.py", line 59, in pisaStory
    pisaParser(src, context, default_css, xhtml, encoding, xml_output)
  File "/Library/Python/2.7/site-packages/xhtml2pdf-0.2b1-py2.7.egg/xhtml2pdf/parser.py", line 708, in pisaParser
    pisaLoop(document, context)
  File "/Library/Python/2.7/site-packages/xhtml2pdf-0.2b1-py2.7.egg/xhtml2pdf/parser.py", line 648, in pisaLoop
    pisaLoop(node, context, path, **kw)
  File "/Library/Python/2.7/site-packages/xhtml2pdf-0.2b1-py2.7.egg/xhtml2pdf/parser.py", line 593, in pisaLoop
    pisaLoop(nnode, context, path, **kw)
  File "/Library/Python/2.7/site-packages/xhtml2pdf-0.2b1-py2.7.egg/xhtml2pdf/parser.py", line 593, in pisaLoop
    pisaLoop(nnode, context, path, **kw)
  File "/Library/Python/2.7/site-packages/xhtml2pdf-0.2b1-py2.7.egg/xhtml2pdf/parser.py", line 593, in pisaLoop
    pisaLoop(nnode, context, path, **kw)
  File "/Library/Python/2.7/site-packages/xhtml2pdf-0.2b1-py2.7.egg/xhtml2pdf/parser.py", line 537, in pisaLoop
    CSS2Frag(context, kw, isBlock)
  File "/Library/Python/2.7/site-packages/xhtml2pdf-0.2b1-py2.7.egg/xhtml2pdf/parser.py", line 285, in CSS2Frag
    c.frag.fontSize = max(getSize("".join(c.cssAttr["font-size"]), c.frag.fontSize, c.baseFontSize), 1.0)
TypeError: sequence item 0: expected string or Unicode, tuple found
Internal Server Error: /pdf/
Traceback (most recent call last):
  File "/Library/Python/2.7/site-packages/django/core/handlers/exception.py", line 39, in inner
    response = get_response(request)
  File "/Library/Python/2.7/site-packages/django/core/handlers/base.py", line 249, in _legacy_get_response
    response = self._get_response(request)
  File "/Library/Python/2.7/site-packages/django/core/handlers/base.py", line 187, in _get_response
    response = self.process_exception_by_middleware(e, request)
  File "/Library/Python/2.7/site-packages/channels/handler.py", line 240, in process_exception_by_middleware
    return super(AsgiHandler, self).process_exception_by_middleware(exception, request)
  File "/Library/Python/2.7/site-packages/django/core/handlers/base.py", line 185, in _get_response
    response = wrapped_callback(request, *callback_args, **callback_kwargs)
  File "/Users/eugenemekhedov/Documents/TFF/School/School/views.py", line 107, in pdf
    'results': results,
  File "/Users/eugenemekhedov/Documents/TFF/School/School/views.py", line 94, in render_to_pdf
    pdf = pisa.pisaDocument(StringIO.StringIO(html.encode("ISO-8859-1")), result)
  File "/Library/Python/2.7/site-packages/xhtml2pdf-0.2b1-py2.7.egg/xhtml2pdf/document.py", line 97, in pisaDocument
    encoding, context=context, xml_output=xml_output)
  File "/Library/Python/2.7/site-packages/xhtml2pdf-0.2b1-py2.7.egg/xhtml2pdf/document.py", line 59, in pisaStory
    pisaParser(src, context, default_css, xhtml, encoding, xml_output)
  File "/Library/Python/2.7/site-packages/xhtml2pdf-0.2b1-py2.7.egg/xhtml2pdf/parser.py", line 708, in pisaParser
    pisaLoop(document, context)
  File "/Library/Python/2.7/site-packages/xhtml2pdf-0.2b1-py2.7.egg/xhtml2pdf/parser.py", line 648, in pisaLoop
    pisaLoop(node, context, path, **kw)
  File "/Library/Python/2.7/site-packages/xhtml2pdf-0.2b1-py2.7.egg/xhtml2pdf/parser.py", line 593, in pisaLoop
    pisaLoop(nnode, context, path, **kw)
  File "/Library/Python/2.7/site-packages/xhtml2pdf-0.2b1-py2.7.egg/xhtml2pdf/parser.py", line 593, in pisaLoop
    pisaLoop(nnode, context, path, **kw)
  File "/Library/Python/2.7/site-packages/xhtml2pdf-0.2b1-py2.7.egg/xhtml2pdf/parser.py", line 593, in pisaLoop
    pisaLoop(nnode, context, path, **kw)
  File "/Library/Python/2.7/site-packages/xhtml2pdf-0.2b1-py2.7.egg/xhtml2pdf/parser.py", line 537, in pisaLoop
    CSS2Frag(context, kw, isBlock)
  File "/Library/Python/2.7/site-packages/xhtml2pdf-0.2b1-py2.7.egg/xhtml2pdf/parser.py", line 285, in CSS2Frag
    c.frag.fontSize = max(getSize("".join(c.cssAttr["font-size"]), c.frag.fontSize, c.baseFontSize), 1.0)
TypeError: sequence item 0: expected string or Unicode, tuple found
Internal Server Error: /pdf/
Traceback (most recent call last):
  File "/Library/Python/2.7/site-packages/django/core/handlers/exception.py", line 39, in inner
    response = get_response(request)
  File "/Library/Python/2.7/site-packages/django/core/handlers/base.py", line 249, in _legacy_get_response
    response = self._get_response(request)
  File "/Library/Python/2.7/site-packages/django/core/handlers/base.py", line 187, in _get_response
    response = self.process_exception_by_middleware(e, request)
  File "/Library/Python/2.7/site-packages/channels/handler.py", line 240, in process_exception_by_middleware
    return super(AsgiHandler, self).process_exception_by_middleware(exception, request)
  File "/Library/Python/2.7/site-packages/django/core/handlers/base.py", line 185, in _get_response
    response = wrapped_callback(request, *callback_args, **callback_kwargs)
  File "/Users/eugenemekhedov/Documents/TFF/School/School/views.py", line 107, in pdf
    'results': results,
  File "/Users/eugenemekhedov/Documents/TFF/School/School/views.py", line 94, in render_to_pdf
    pdf = pisa.pisaDocument(StringIO.StringIO(html.encode("ISO-8859-1")), result)
  File "/Library/Python/2.7/site-packages/xhtml2pdf-0.2b1-py2.7.egg/xhtml2pdf/document.py", line 97, in pisaDocument
    encoding, context=context, xml_output=xml_output)
  File "/Library/Python/2.7/site-packages/xhtml2pdf-0.2b1-py2.7.egg/xhtml2pdf/document.py", line 59, in pisaStory
    pisaParser(src, context, default_css, xhtml, encoding, xml_output)
  File "/Library/Python/2.7/site-packages/xhtml2pdf-0.2b1-py2.7.egg/xhtml2pdf/parser.py", line 702, in pisaParser
    context.parseCSS()
  File "/Library/Python/2.7/site-packages/xhtml2pdf-0.2b1-py2.7.egg/xhtml2pdf/context.py", line 522, in parseCSS
    self.css = self.cssParser.parse(self.cssText)
  File "/Library/Python/2.7/site-packages/xhtml2pdf-0.2b1-py2.7.egg/xhtml2pdf/w3c/cssParser.py", line 443, in parse
    src, stylesheet = self._parseStylesheet(src)
  File "/Library/Python/2.7/site-packages/xhtml2pdf-0.2b1-py2.7.egg/xhtml2pdf/w3c/cssParser.py", line 542, in _parseStylesheet
    src, atResults = self._parseAtKeyword(src)
  File "/Library/Python/2.7/site-packages/xhtml2pdf-0.2b1-py2.7.egg/xhtml2pdf/w3c/cssParser.py", line 662, in _parseAtKeyword
    src, result = self._parseAtPage(src)
  File "/Library/Python/2.7/site-packages/xhtml2pdf-0.2b1-py2.7.egg/xhtml2pdf/w3c/cssParser.py", line 773, in _parseAtPage
    result = [self.cssBuilder.atPage(page, pseudopage, properties)]
  File "/Library/Python/2.7/site-packages/xhtml2pdf-0.2b1-py2.7.egg/xhtml2pdf/context.py", line 266, in atPage
    raise RuntimeError("Unknown size value for @page")
RuntimeError: Unknown size value for @page
Internal Server Error: /admin/apply/destribution/
Traceback (most recent call last):
  File "/Library/Python/2.7/site-packages/django/core/handlers/exception.py", line 39, in inner
    response = get_response(request)
  File "/Library/Python/2.7/site-packages/django/core/handlers/base.py", line 249, in _legacy_get_response
    response = self._get_response(request)
  File "/Library/Python/2.7/site-packages/django/core/handlers/base.py", line 187, in _get_response
    response = self.process_exception_by_middleware(e, request)
  File "/Library/Python/2.7/site-packages/channels/handler.py", line 240, in process_exception_by_middleware
    return super(AsgiHandler, self).process_exception_by_middleware(exception, request)
  File "/Library/Python/2.7/site-packages/django/core/handlers/base.py", line 185, in _get_response
    response = wrapped_callback(request, *callback_args, **callback_kwargs)
  File "/Library/Python/2.7/site-packages/django/contrib/admin/options.py", line 544, in wrapper
    return self.admin_site.admin_view(view)(*args, **kwargs)
  File "/Library/Python/2.7/site-packages/django/utils/decorators.py", line 149, in _wrapped_view
    response = view_func(request, *args, **kwargs)
  File "/Library/Python/2.7/site-packages/django/views/decorators/cache.py", line 57, in _wrapped_view_func
    response = view_func(request, *args, **kwargs)
  File "/Library/Python/2.7/site-packages/django/contrib/admin/sites.py", line 211, in inner
    return view(request, *args, **kwargs)
  File "/Library/Python/2.7/site-packages/django/utils/decorators.py", line 67, in _wrapper
    return bound_func(*args, **kwargs)
  File "/Library/Python/2.7/site-packages/django/utils/decorators.py", line 149, in _wrapped_view
    response = view_func(request, *args, **kwargs)
  File "/Library/Python/2.7/site-packages/django/utils/decorators.py", line 63, in bound_func
    return func.__get__(self, type(self))(*args2, **kwargs2)
  File "/Library/Python/2.7/site-packages/django/contrib/admin/options.py", line 1569, in changelist_view
    response = self.response_action(request, queryset=cl.get_queryset(request))
  File "/Library/Python/2.7/site-packages/django/contrib/admin/options.py", line 1305, in response_action
    response = func(self, request, queryset)
  File "/Users/eugenemekhedov/Documents/TFF/School/apply/admin.py", line 496, in send_certificates
    member
  File "/Users/eugenemekhedov/Documents/TFF/School/apply/admin.py", line 480, in render_to_pdf
    email.send()
  File "/Library/Python/2.7/site-packages/django/core/mail/message.py", line 342, in send
    return self.get_connection(fail_silently).send_messages([self])
  File "/Library/Python/2.7/site-packages/django/core/mail/backends/smtp.py", line 107, in send_messages
    sent = self._send(message)
  File "/Library/Python/2.7/site-packages/django/core/mail/backends/smtp.py", line 121, in _send
    message = email_message.message()
  File "/Library/Python/2.7/site-packages/django/core/mail/message.py", line 306, in message
    msg = self._create_message(msg)
  File "/Library/Python/2.7/site-packages/django/core/mail/message.py", line 394, in _create_message
    return self._create_attachments(msg)
  File "/Library/Python/2.7/site-packages/django/core/mail/message.py", line 407, in _create_attachments
    msg.attach(self._create_attachment(*attachment))
  File "/Library/Python/2.7/site-packages/django/core/mail/message.py", line 449, in _create_attachment
    attachment = self._create_mime_attachment(content, mimetype)
  File "/Library/Python/2.7/site-packages/django/core/mail/message.py", line 437, in _create_mime_attachment
    Encoders.encode_base64(attachment)
  File "/System/Library/Frameworks/Python.framework/Versions/2.7/lib/python2.7/email/encoders.py", line 45, in encode_base64
    encdata = _bencode(orig)
  File "/System/Library/Frameworks/Python.framework/Versions/2.7/lib/python2.7/email/encoders.py", line 31, in _bencode
    hasnewline = (s[-1] == '\n')
TypeError: 'pisaContext' object does not support indexing
Internal Server Error: /admin/apply/destribution/
Traceback (most recent call last):
  File "/Library/Python/2.7/site-packages/django/core/handlers/exception.py", line 39, in inner
    response = get_response(request)
  File "/Library/Python/2.7/site-packages/django/core/handlers/base.py", line 249, in _legacy_get_response
    response = self._get_response(request)
  File "/Library/Python/2.7/site-packages/django/core/handlers/base.py", line 187, in _get_response
    response = self.process_exception_by_middleware(e, request)
  File "/Library/Python/2.7/site-packages/channels/handler.py", line 240, in process_exception_by_middleware
    return super(AsgiHandler, self).process_exception_by_middleware(exception, request)
  File "/Library/Python/2.7/site-packages/django/core/handlers/base.py", line 185, in _get_response
    response = wrapped_callback(request, *callback_args, **callback_kwargs)
  File "/Library/Python/2.7/site-packages/django/contrib/admin/options.py", line 544, in wrapper
    return self.admin_site.admin_view(view)(*args, **kwargs)
  File "/Library/Python/2.7/site-packages/django/utils/decorators.py", line 149, in _wrapped_view
    response = view_func(request, *args, **kwargs)
  File "/Library/Python/2.7/site-packages/django/views/decorators/cache.py", line 57, in _wrapped_view_func
    response = view_func(request, *args, **kwargs)
  File "/Library/Python/2.7/site-packages/django/contrib/admin/sites.py", line 211, in inner
    return view(request, *args, **kwargs)
  File "/Library/Python/2.7/site-packages/django/utils/decorators.py", line 67, in _wrapper
    return bound_func(*args, **kwargs)
  File "/Library/Python/2.7/site-packages/django/utils/decorators.py", line 149, in _wrapped_view
    response = view_func(request, *args, **kwargs)
  File "/Library/Python/2.7/site-packages/django/utils/decorators.py", line 63, in bound_func
    return func.__get__(self, type(self))(*args2, **kwargs2)
  File "/Library/Python/2.7/site-packages/django/contrib/admin/options.py", line 1569, in changelist_view
    response = self.response_action(request, queryset=cl.get_queryset(request))
  File "/Library/Python/2.7/site-packages/django/contrib/admin/options.py", line 1305, in response_action
    response = func(self, request, queryset)
  File "/Users/eugenemekhedov/Documents/TFF/School/apply/admin.py", line 446, in send_email
    "\nLet's stay in touch! Summer school starts 12 July. You'll receive further information on your email and also at " + project + "\n See you later!"
AttributeError: 'Destribution' object has no attribute 'name'
Internal Server Error: /admin/apply/destribution/
Traceback (most recent call last):
  File "/Library/Python/2.7/site-packages/django/core/handlers/exception.py", line 39, in inner
    response = get_response(request)
  File "/Library/Python/2.7/site-packages/django/core/handlers/base.py", line 249, in _legacy_get_response
    response = self._get_response(request)
  File "/Library/Python/2.7/site-packages/django/core/handlers/base.py", line 187, in _get_response
    response = self.process_exception_by_middleware(e, request)
  File "/Library/Python/2.7/site-packages/channels/handler.py", line 240, in process_exception_by_middleware
    return super(AsgiHandler, self).process_exception_by_middleware(exception, request)
  File "/Library/Python/2.7/site-packages/django/core/handlers/base.py", line 185, in _get_response
    response = wrapped_callback(request, *callback_args, **callback_kwargs)
  File "/Library/Python/2.7/site-packages/django/contrib/admin/options.py", line 544, in wrapper
    return self.admin_site.admin_view(view)(*args, **kwargs)
  File "/Library/Python/2.7/site-packages/django/utils/decorators.py", line 149, in _wrapped_view
    response = view_func(request, *args, **kwargs)
  File "/Library/Python/2.7/site-packages/django/views/decorators/cache.py", line 57, in _wrapped_view_func
    response = view_func(request, *args, **kwargs)
  File "/Library/Python/2.7/site-packages/django/contrib/admin/sites.py", line 211, in inner
    return view(request, *args, **kwargs)
  File "/Library/Python/2.7/site-packages/django/utils/decorators.py", line 67, in _wrapper
    return bound_func(*args, **kwargs)
  File "/Library/Python/2.7/site-packages/django/utils/decorators.py", line 149, in _wrapped_view
    response = view_func(request, *args, **kwargs)
  File "/Library/Python/2.7/site-packages/django/utils/decorators.py", line 63, in bound_func
    return func.__get__(self, type(self))(*args2, **kwargs2)
  File "/Library/Python/2.7/site-packages/django/contrib/admin/options.py", line 1569, in changelist_view
    response = self.response_action(request, queryset=cl.get_queryset(request))
  File "/Library/Python/2.7/site-packages/django/contrib/admin/options.py", line 1305, in response_action
    response = func(self, request, queryset)
  File "/Users/eugenemekhedov/Documents/TFF/School/apply/admin.py", line 446, in send_email
    "\nLet's stay in touch! Summer school starts 12 July. You'll receive further information on your email and also at " + project + "\n See you later!"
AttributeError: 'Destribution' object has no attribute 'name'
Internal Server Error: /admin/apply/destribution/
Traceback (most recent call last):
  File "/Library/Python/2.7/site-packages/django/core/handlers/exception.py", line 39, in inner
    response = get_response(request)
  File "/Library/Python/2.7/site-packages/django/core/handlers/base.py", line 249, in _legacy_get_response
    response = self._get_response(request)
  File "/Library/Python/2.7/site-packages/django/core/handlers/base.py", line 187, in _get_response
    response = self.process_exception_by_middleware(e, request)
  File "/Library/Python/2.7/site-packages/channels/handler.py", line 240, in process_exception_by_middleware
    return super(AsgiHandler, self).process_exception_by_middleware(exception, request)
  File "/Library/Python/2.7/site-packages/django/core/handlers/base.py", line 185, in _get_response
    response = wrapped_callback(request, *callback_args, **callback_kwargs)
  File "/Library/Python/2.7/site-packages/django/contrib/admin/options.py", line 544, in wrapper
    return self.admin_site.admin_view(view)(*args, **kwargs)
  File "/Library/Python/2.7/site-packages/django/utils/decorators.py", line 149, in _wrapped_view
    response = view_func(request, *args, **kwargs)
  File "/Library/Python/2.7/site-packages/django/views/decorators/cache.py", line 57, in _wrapped_view_func
    response = view_func(request, *args, **kwargs)
  File "/Library/Python/2.7/site-packages/django/contrib/admin/sites.py", line 211, in inner
    return view(request, *args, **kwargs)
  File "/Library/Python/2.7/site-packages/django/utils/decorators.py", line 67, in _wrapper
    return bound_func(*args, **kwargs)
  File "/Library/Python/2.7/site-packages/django/utils/decorators.py", line 149, in _wrapped_view
    response = view_func(request, *args, **kwargs)
  File "/Library/Python/2.7/site-packages/django/utils/decorators.py", line 63, in bound_func
    return func.__get__(self, type(self))(*args2, **kwargs2)
  File "/Library/Python/2.7/site-packages/django/contrib/admin/options.py", line 1569, in changelist_view
    response = self.response_action(request, queryset=cl.get_queryset(request))
  File "/Library/Python/2.7/site-packages/django/contrib/admin/options.py", line 1305, in response_action
    response = func(self, request, queryset)
  File "/Users/eugenemekhedov/Documents/TFF/School/apply/admin.py", line 446, in send_email
    "\nLet's stay in touch! Summer school starts 12 July. You'll receive further information on your email and also at " + project + "\n See you later!"
TypeError: coercing to Unicode: need string or buffer, long found
Internal Server Error: /admin/apply/destribution/
Traceback (most recent call last):
  File "/Library/Python/2.7/site-packages/django/core/handlers/exception.py", line 39, in inner
    response = get_response(request)
  File "/Library/Python/2.7/site-packages/django/core/handlers/base.py", line 249, in _legacy_get_response
    response = self._get_response(request)
  File "/Library/Python/2.7/site-packages/django/core/handlers/base.py", line 187, in _get_response
    response = self.process_exception_by_middleware(e, request)
  File "/Library/Python/2.7/site-packages/channels/handler.py", line 240, in process_exception_by_middleware
    return super(AsgiHandler, self).process_exception_by_middleware(exception, request)
  File "/Library/Python/2.7/site-packages/django/core/handlers/base.py", line 185, in _get_response
    response = wrapped_callback(request, *callback_args, **callback_kwargs)
  File "/Library/Python/2.7/site-packages/django/contrib/admin/options.py", line 544, in wrapper
    return self.admin_site.admin_view(view)(*args, **kwargs)
  File "/Library/Python/2.7/site-packages/django/utils/decorators.py", line 149, in _wrapped_view
    response = view_func(request, *args, **kwargs)
  File "/Library/Python/2.7/site-packages/django/views/decorators/cache.py", line 57, in _wrapped_view_func
    response = view_func(request, *args, **kwargs)
  File "/Library/Python/2.7/site-packages/django/contrib/admin/sites.py", line 211, in inner
    return view(request, *args, **kwargs)
  File "/Library/Python/2.7/site-packages/django/utils/decorators.py", line 67, in _wrapper
    return bound_func(*args, **kwargs)
  File "/Library/Python/2.7/site-packages/django/utils/decorators.py", line 149, in _wrapped_view
    response = view_func(request, *args, **kwargs)
  File "/Library/Python/2.7/site-packages/django/utils/decorators.py", line 63, in bound_func
    return func.__get__(self, type(self))(*args2, **kwargs2)
  File "/Library/Python/2.7/site-packages/django/contrib/admin/options.py", line 1569, in changelist_view
    response = self.response_action(request, queryset=cl.get_queryset(request))
  File "/Library/Python/2.7/site-packages/django/contrib/admin/options.py", line 1305, in response_action
    response = func(self, request, queryset)
  File "/Users/eugenemekhedov/Documents/TFF/School/apply/admin.py", line 446, in send_email
    "\nLet's stay in touch! Summer school starts 12 July. You'll receive further information on your email and also at " + project + "\n See you later!"
TypeError: coercing to Unicode: need string or buffer, long found
Internal Server Error: /admin/apply/destribution/
Traceback (most recent call last):
  File "/Library/Python/2.7/site-packages/django/core/handlers/exception.py", line 39, in inner
    response = get_response(request)
  File "/Library/Python/2.7/site-packages/django/core/handlers/base.py", line 249, in _legacy_get_response
    response = self._get_response(request)
  File "/Library/Python/2.7/site-packages/django/core/handlers/base.py", line 187, in _get_response
    response = self.process_exception_by_middleware(e, request)
  File "/Library/Python/2.7/site-packages/channels/handler.py", line 240, in process_exception_by_middleware
    return super(AsgiHandler, self).process_exception_by_middleware(exception, request)
  File "/Library/Python/2.7/site-packages/django/core/handlers/base.py", line 185, in _get_response
    response = wrapped_callback(request, *callback_args, **callback_kwargs)
  File "/Library/Python/2.7/site-packages/django/contrib/admin/options.py", line 544, in wrapper
    return self.admin_site.admin_view(view)(*args, **kwargs)
  File "/Library/Python/2.7/site-packages/django/utils/decorators.py", line 149, in _wrapped_view
    response = view_func(request, *args, **kwargs)
  File "/Library/Python/2.7/site-packages/django/views/decorators/cache.py", line 57, in _wrapped_view_func
    response = view_func(request, *args, **kwargs)
  File "/Library/Python/2.7/site-packages/django/contrib/admin/sites.py", line 211, in inner
    return view(request, *args, **kwargs)
  File "/Library/Python/2.7/site-packages/django/utils/decorators.py", line 67, in _wrapper
    return bound_func(*args, **kwargs)
  File "/Library/Python/2.7/site-packages/django/utils/decorators.py", line 149, in _wrapped_view
    response = view_func(request, *args, **kwargs)
  File "/Library/Python/2.7/site-packages/django/utils/decorators.py", line 63, in bound_func
    return func.__get__(self, type(self))(*args2, **kwargs2)
  File "/Library/Python/2.7/site-packages/django/contrib/admin/options.py", line 1569, in changelist_view
    response = self.response_action(request, queryset=cl.get_queryset(request))
  File "/Library/Python/2.7/site-packages/django/contrib/admin/options.py", line 1305, in response_action
    response = func(self, request, queryset)
  File "/Users/eugenemekhedov/Documents/TFF/School/apply/admin.py", line 446, in send_email
    "\nLet's stay in touch! Summer school starts 12 July. You'll receive further information on your email and also at " + project + "\n See you later!"
TypeError: coercing to Unicode: need string or buffer, long found
Internal Server Error: /admin/apply/destribution/
Traceback (most recent call last):
  File "/Library/Python/2.7/site-packages/django/core/handlers/exception.py", line 39, in inner
    response = get_response(request)
  File "/Library/Python/2.7/site-packages/django/core/handlers/base.py", line 249, in _legacy_get_response
    response = self._get_response(request)
  File "/Library/Python/2.7/site-packages/django/core/handlers/base.py", line 187, in _get_response
    response = self.process_exception_by_middleware(e, request)
  File "/Library/Python/2.7/site-packages/channels/handler.py", line 240, in process_exception_by_middleware
    return super(AsgiHandler, self).process_exception_by_middleware(exception, request)
  File "/Library/Python/2.7/site-packages/django/core/handlers/base.py", line 185, in _get_response
    response = wrapped_callback(request, *callback_args, **callback_kwargs)
  File "/Library/Python/2.7/site-packages/django/contrib/admin/options.py", line 544, in wrapper
    return self.admin_site.admin_view(view)(*args, **kwargs)
  File "/Library/Python/2.7/site-packages/django/utils/decorators.py", line 149, in _wrapped_view
    response = view_func(request, *args, **kwargs)
  File "/Library/Python/2.7/site-packages/django/views/decorators/cache.py", line 57, in _wrapped_view_func
    response = view_func(request, *args, **kwargs)
  File "/Library/Python/2.7/site-packages/django/contrib/admin/sites.py", line 211, in inner
    return view(request, *args, **kwargs)
  File "/Library/Python/2.7/site-packages/django/utils/decorators.py", line 67, in _wrapper
    return bound_func(*args, **kwargs)
  File "/Library/Python/2.7/site-packages/django/utils/decorators.py", line 149, in _wrapped_view
    response = view_func(request, *args, **kwargs)
  File "/Library/Python/2.7/site-packages/django/utils/decorators.py", line 63, in bound_func
    return func.__get__(self, type(self))(*args2, **kwargs2)
  File "/Library/Python/2.7/site-packages/django/contrib/admin/options.py", line 1569, in changelist_view
    response = self.response_action(request, queryset=cl.get_queryset(request))
  File "/Library/Python/2.7/site-packages/django/contrib/admin/options.py", line 1305, in response_action
    response = func(self, request, queryset)
  File "/Users/eugenemekhedov/Documents/TFF/School/apply/admin.py", line 446, in send_email
    "\nLet's stay in touch! Summer school starts 12 July. You'll receive further information on your email and also at " + project + "\n See you later!"
TypeError: coercing to Unicode: need string or buffer, long found
Internal Server Error: /admin/apply/destribution/
Traceback (most recent call last):
  File "/Library/Python/2.7/site-packages/django/core/handlers/exception.py", line 39, in inner
    response = get_response(request)
  File "/Library/Python/2.7/site-packages/django/core/handlers/base.py", line 249, in _legacy_get_response
    response = self._get_response(request)
  File "/Library/Python/2.7/site-packages/django/core/handlers/base.py", line 187, in _get_response
    response = self.process_exception_by_middleware(e, request)
  File "/Library/Python/2.7/site-packages/channels/handler.py", line 240, in process_exception_by_middleware
    return super(AsgiHandler, self).process_exception_by_middleware(exception, request)
  File "/Library/Python/2.7/site-packages/django/core/handlers/base.py", line 185, in _get_response
    response = wrapped_callback(request, *callback_args, **callback_kwargs)
  File "/Library/Python/2.7/site-packages/django/contrib/admin/options.py", line 544, in wrapper
    return self.admin_site.admin_view(view)(*args, **kwargs)
  File "/Library/Python/2.7/site-packages/django/utils/decorators.py", line 149, in _wrapped_view
    response = view_func(request, *args, **kwargs)
  File "/Library/Python/2.7/site-packages/django/views/decorators/cache.py", line 57, in _wrapped_view_func
    response = view_func(request, *args, **kwargs)
  File "/Library/Python/2.7/site-packages/django/contrib/admin/sites.py", line 211, in inner
    return view(request, *args, **kwargs)
  File "/Library/Python/2.7/site-packages/django/utils/decorators.py", line 67, in _wrapper
    return bound_func(*args, **kwargs)
  File "/Library/Python/2.7/site-packages/django/utils/decorators.py", line 149, in _wrapped_view
    response = view_func(request, *args, **kwargs)
  File "/Library/Python/2.7/site-packages/django/utils/decorators.py", line 63, in bound_func
    return func.__get__(self, type(self))(*args2, **kwargs2)
  File "/Library/Python/2.7/site-packages/django/contrib/admin/options.py", line 1569, in changelist_view
    response = self.response_action(request, queryset=cl.get_queryset(request))
  File "/Library/Python/2.7/site-packages/django/contrib/admin/options.py", line 1305, in response_action
    response = func(self, request, queryset)
  File "/Users/eugenemekhedov/Documents/TFF/School/apply/admin.py", line 446, in send_email
    "\nLet's stay in touch! Summer school starts 12 July. You'll receive further information on your email and also at " + project + "\n See you later!"
TypeError: coercing to Unicode: need string or buffer, long found
Internal Server Error: /admin/apply/destribution/
Traceback (most recent call last):
  File "/Library/Python/2.7/site-packages/django/core/handlers/exception.py", line 39, in inner
    response = get_response(request)
  File "/Library/Python/2.7/site-packages/django/core/handlers/base.py", line 249, in _legacy_get_response
    response = self._get_response(request)
  File "/Library/Python/2.7/site-packages/django/core/handlers/base.py", line 187, in _get_response
    response = self.process_exception_by_middleware(e, request)
  File "/Library/Python/2.7/site-packages/channels/handler.py", line 240, in process_exception_by_middleware
    return super(AsgiHandler, self).process_exception_by_middleware(exception, request)
  File "/Library/Python/2.7/site-packages/django/core/handlers/base.py", line 185, in _get_response
    response = wrapped_callback(request, *callback_args, **callback_kwargs)
  File "/Library/Python/2.7/site-packages/django/contrib/admin/options.py", line 544, in wrapper
    return self.admin_site.admin_view(view)(*args, **kwargs)
  File "/Library/Python/2.7/site-packages/django/utils/decorators.py", line 149, in _wrapped_view
    response = view_func(request, *args, **kwargs)
  File "/Library/Python/2.7/site-packages/django/views/decorators/cache.py", line 57, in _wrapped_view_func
    response = view_func(request, *args, **kwargs)
  File "/Library/Python/2.7/site-packages/django/contrib/admin/sites.py", line 211, in inner
    return view(request, *args, **kwargs)
  File "/Library/Python/2.7/site-packages/django/utils/decorators.py", line 67, in _wrapper
    return bound_func(*args, **kwargs)
  File "/Library/Python/2.7/site-packages/django/utils/decorators.py", line 149, in _wrapped_view
    response = view_func(request, *args, **kwargs)
  File "/Library/Python/2.7/site-packages/django/utils/decorators.py", line 63, in bound_func
    return func.__get__(self, type(self))(*args2, **kwargs2)
  File "/Library/Python/2.7/site-packages/django/contrib/admin/options.py", line 1569, in changelist_view
    response = self.response_action(request, queryset=cl.get_queryset(request))
  File "/Library/Python/2.7/site-packages/django/contrib/admin/options.py", line 1305, in response_action
    response = func(self, request, queryset)
  File "/Users/eugenemekhedov/Documents/TFF/School/apply/admin.py", line 445, in send_email
    " You have contributed to " + project + "\nHere you login data:\nlogin: " + member.member_id.name + "\npassword:" + member.member_id.id + member.member_id.name +"\nYou can change it on personal page -> edit profile" \
TypeError: coercing to Unicode: need string or buffer, long found
Internal Server Error: /admin/apply/destribution/
Traceback (most recent call last):
  File "/Library/Python/2.7/site-packages/django/core/handlers/exception.py", line 39, in inner
    response = get_response(request)
  File "/Library/Python/2.7/site-packages/django/core/handlers/base.py", line 249, in _legacy_get_response
    response = self._get_response(request)
  File "/Library/Python/2.7/site-packages/django/core/handlers/base.py", line 187, in _get_response
    response = self.process_exception_by_middleware(e, request)
  File "/Library/Python/2.7/site-packages/channels/handler.py", line 240, in process_exception_by_middleware
    return super(AsgiHandler, self).process_exception_by_middleware(exception, request)
  File "/Library/Python/2.7/site-packages/django/core/handlers/base.py", line 185, in _get_response
    response = wrapped_callback(request, *callback_args, **callback_kwargs)
  File "/Library/Python/2.7/site-packages/django/contrib/admin/options.py", line 544, in wrapper
    return self.admin_site.admin_view(view)(*args, **kwargs)
  File "/Library/Python/2.7/site-packages/django/utils/decorators.py", line 149, in _wrapped_view
    response = view_func(request, *args, **kwargs)
  File "/Library/Python/2.7/site-packages/django/views/decorators/cache.py", line 57, in _wrapped_view_func
    response = view_func(request, *args, **kwargs)
  File "/Library/Python/2.7/site-packages/django/contrib/admin/sites.py", line 211, in inner
    return view(request, *args, **kwargs)
  File "/Library/Python/2.7/site-packages/django/utils/decorators.py", line 67, in _wrapper
    return bound_func(*args, **kwargs)
  File "/Library/Python/2.7/site-packages/django/utils/decorators.py", line 149, in _wrapped_view
    response = view_func(request, *args, **kwargs)
  File "/Library/Python/2.7/site-packages/django/utils/decorators.py", line 63, in bound_func
    return func.__get__(self, type(self))(*args2, **kwargs2)
  File "/Library/Python/2.7/site-packages/django/contrib/admin/options.py", line 1569, in changelist_view
    response = self.response_action(request, queryset=cl.get_queryset(request))
  File "/Library/Python/2.7/site-packages/django/contrib/admin/options.py", line 1305, in response_action
    response = func(self, request, queryset)
  File "/Users/eugenemekhedov/Documents/TFF/School/apply/admin.py", line 445, in send_email
    " You have contributed to " + project.project_name + "\nHere you login data:\nlogin: " + member.member_id.name + "\npassword:" + member.member_id.id + member.member_id.name +"\nYou can change it on personal page -> edit profile" \
TypeError: coercing to Unicode: need string or buffer, long found
Internal Server Error: /admin/apply/destribution/
Traceback (most recent call last):
  File "/Library/Python/2.7/site-packages/django/core/handlers/exception.py", line 39, in inner
    response = get_response(request)
  File "/Library/Python/2.7/site-packages/django/core/handlers/base.py", line 249, in _legacy_get_response
    response = self._get_response(request)
  File "/Library/Python/2.7/site-packages/django/core/handlers/base.py", line 187, in _get_response
    response = self.process_exception_by_middleware(e, request)
  File "/Library/Python/2.7/site-packages/channels/handler.py", line 240, in process_exception_by_middleware
    return super(AsgiHandler, self).process_exception_by_middleware(exception, request)
  File "/Library/Python/2.7/site-packages/django/core/handlers/base.py", line 185, in _get_response
    response = wrapped_callback(request, *callback_args, **callback_kwargs)
  File "/Library/Python/2.7/site-packages/django/contrib/admin/options.py", line 544, in wrapper
    return self.admin_site.admin_view(view)(*args, **kwargs)
  File "/Library/Python/2.7/site-packages/django/utils/decorators.py", line 149, in _wrapped_view
    response = view_func(request, *args, **kwargs)
  File "/Library/Python/2.7/site-packages/django/views/decorators/cache.py", line 57, in _wrapped_view_func
    response = view_func(request, *args, **kwargs)
  File "/Library/Python/2.7/site-packages/django/contrib/admin/sites.py", line 211, in inner
    return view(request, *args, **kwargs)
  File "/Library/Python/2.7/site-packages/django/utils/decorators.py", line 67, in _wrapper
    return bound_func(*args, **kwargs)
  File "/Library/Python/2.7/site-packages/django/utils/decorators.py", line 149, in _wrapped_view
    response = view_func(request, *args, **kwargs)
  File "/Library/Python/2.7/site-packages/django/utils/decorators.py", line 63, in bound_func
    return func.__get__(self, type(self))(*args2, **kwargs2)
  File "/Library/Python/2.7/site-packages/django/contrib/admin/options.py", line 1569, in changelist_view
    response = self.response_action(request, queryset=cl.get_queryset(request))
  File "/Library/Python/2.7/site-packages/django/contrib/admin/options.py", line 1305, in response_action
    response = func(self, request, queryset)
  File "/Users/eugenemekhedov/Documents/TFF/School/apply/admin.py", line 445, in send_email
    " You have contributed to " + project.project_name + "\nHere you login data:\nlogin: " + member.member_id.name + "\npassword:" + member.member_id.id + member.member_id.name +"\nYou can change it on personal page -> edit profile" \
TypeError: coercing to Unicode: need string or buffer, long found
Internal Server Error: /admin/apply/destribution/
Traceback (most recent call last):
  File "/Library/Python/2.7/site-packages/django/core/handlers/exception.py", line 39, in inner
    response = get_response(request)
  File "/Library/Python/2.7/site-packages/django/core/handlers/base.py", line 249, in _legacy_get_response
    response = self._get_response(request)
  File "/Library/Python/2.7/site-packages/django/core/handlers/base.py", line 187, in _get_response
    response = self.process_exception_by_middleware(e, request)
  File "/Library/Python/2.7/site-packages/channels/handler.py", line 240, in process_exception_by_middleware
    return super(AsgiHandler, self).process_exception_by_middleware(exception, request)
  File "/Library/Python/2.7/site-packages/django/core/handlers/base.py", line 185, in _get_response
    response = wrapped_callback(request, *callback_args, **callback_kwargs)
  File "/Library/Python/2.7/site-packages/django/contrib/admin/options.py", line 544, in wrapper
    return self.admin_site.admin_view(view)(*args, **kwargs)
  File "/Library/Python/2.7/site-packages/django/utils/decorators.py", line 149, in _wrapped_view
    response = view_func(request, *args, **kwargs)
  File "/Library/Python/2.7/site-packages/django/views/decorators/cache.py", line 57, in _wrapped_view_func
    response = view_func(request, *args, **kwargs)
  File "/Library/Python/2.7/site-packages/django/contrib/admin/sites.py", line 211, in inner
    return view(request, *args, **kwargs)
  File "/Library/Python/2.7/site-packages/django/utils/decorators.py", line 67, in _wrapper
    return bound_func(*args, **kwargs)
  File "/Library/Python/2.7/site-packages/django/utils/decorators.py", line 149, in _wrapped_view
    response = view_func(request, *args, **kwargs)
  File "/Library/Python/2.7/site-packages/django/utils/decorators.py", line 63, in bound_func
    return func.__get__(self, type(self))(*args2, **kwargs2)
  File "/Library/Python/2.7/site-packages/django/contrib/admin/options.py", line 1569, in changelist_view
    response = self.response_action(request, queryset=cl.get_queryset(request))
  File "/Library/Python/2.7/site-packages/django/contrib/admin/options.py", line 1305, in response_action
    response = func(self, request, queryset)
  File "/Users/eugenemekhedov/Documents/TFF/School/apply/admin.py", line 445, in send_email
    " You have contributed to " + project.project_name + "\nHere you login data:\nlogin: " + member.member_id.name + "\npassword:" + member.member_id.id + member.member_id.name +"\nYou can change it on personal page -> edit profile" \
TypeError: coercing to Unicode: need string or buffer, long found
Internal Server Error: /admin/apply/destribution/
Traceback (most recent call last):
  File "/Library/Python/2.7/site-packages/django/core/handlers/exception.py", line 39, in inner
    response = get_response(request)
  File "/Library/Python/2.7/site-packages/django/core/handlers/base.py", line 249, in _legacy_get_response
    response = self._get_response(request)
  File "/Library/Python/2.7/site-packages/django/core/handlers/base.py", line 187, in _get_response
    response = self.process_exception_by_middleware(e, request)
  File "/Library/Python/2.7/site-packages/channels/handler.py", line 240, in process_exception_by_middleware
    return super(AsgiHandler, self).process_exception_by_middleware(exception, request)
  File "/Library/Python/2.7/site-packages/django/core/handlers/base.py", line 185, in _get_response
    response = wrapped_callback(request, *callback_args, **callback_kwargs)
  File "/Library/Python/2.7/site-packages/django/contrib/admin/options.py", line 544, in wrapper
    return self.admin_site.admin_view(view)(*args, **kwargs)
  File "/Library/Python/2.7/site-packages/django/utils/decorators.py", line 149, in _wrapped_view
    response = view_func(request, *args, **kwargs)
  File "/Library/Python/2.7/site-packages/django/views/decorators/cache.py", line 57, in _wrapped_view_func
    response = view_func(request, *args, **kwargs)
  File "/Library/Python/2.7/site-packages/django/contrib/admin/sites.py", line 211, in inner
    return view(request, *args, **kwargs)
  File "/Library/Python/2.7/site-packages/django/utils/decorators.py", line 67, in _wrapper
    return bound_func(*args, **kwargs)
  File "/Library/Python/2.7/site-packages/django/utils/decorators.py", line 149, in _wrapped_view
    response = view_func(request, *args, **kwargs)
  File "/Library/Python/2.7/site-packages/django/utils/decorators.py", line 63, in bound_func
    return func.__get__(self, type(self))(*args2, **kwargs2)
  File "/Library/Python/2.7/site-packages/django/contrib/admin/options.py", line 1569, in changelist_view
    response = self.response_action(request, queryset=cl.get_queryset(request))
  File "/Library/Python/2.7/site-packages/django/contrib/admin/options.py", line 1305, in response_action
    response = func(self, request, queryset)
  File "/Users/eugenemekhedov/Documents/TFF/School/apply/admin.py", line 445, in send_email
    " You have contributed to " + "project_name " + "\nHere you login data:\nlogin: " + member.member_id.name + "\npassword:" + member.member_id.id + member.member_id.name +"\nYou can change it on personal page -> edit profile" \
TypeError: coercing to Unicode: need string or buffer, long found
Internal Server Error: /admin/apply/destribution/
Traceback (most recent call last):
  File "/Library/Python/2.7/site-packages/django/core/handlers/exception.py", line 39, in inner
    response = get_response(request)
  File "/Library/Python/2.7/site-packages/django/core/handlers/base.py", line 249, in _legacy_get_response
    response = self._get_response(request)
  File "/Library/Python/2.7/site-packages/django/core/handlers/base.py", line 187, in _get_response
    response = self.process_exception_by_middleware(e, request)
  File "/Library/Python/2.7/site-packages/channels/handler.py", line 240, in process_exception_by_middleware
    return super(AsgiHandler, self).process_exception_by_middleware(exception, request)
  File "/Library/Python/2.7/site-packages/django/core/handlers/base.py", line 185, in _get_response
    response = wrapped_callback(request, *callback_args, **callback_kwargs)
  File "/Library/Python/2.7/site-packages/django/contrib/admin/options.py", line 544, in wrapper
    return self.admin_site.admin_view(view)(*args, **kwargs)
  File "/Library/Python/2.7/site-packages/django/utils/decorators.py", line 149, in _wrapped_view
    response = view_func(request, *args, **kwargs)
  File "/Library/Python/2.7/site-packages/django/views/decorators/cache.py", line 57, in _wrapped_view_func
    response = view_func(request, *args, **kwargs)
  File "/Library/Python/2.7/site-packages/django/contrib/admin/sites.py", line 211, in inner
    return view(request, *args, **kwargs)
  File "/Library/Python/2.7/site-packages/django/utils/decorators.py", line 67, in _wrapper
    return bound_func(*args, **kwargs)
  File "/Library/Python/2.7/site-packages/django/utils/decorators.py", line 149, in _wrapped_view
    response = view_func(request, *args, **kwargs)
  File "/Library/Python/2.7/site-packages/django/utils/decorators.py", line 63, in bound_func
    return func.__get__(self, type(self))(*args2, **kwargs2)
  File "/Library/Python/2.7/site-packages/django/contrib/admin/options.py", line 1569, in changelist_view
    response = self.response_action(request, queryset=cl.get_queryset(request))
  File "/Library/Python/2.7/site-packages/django/contrib/admin/options.py", line 1305, in response_action
    response = func(self, request, queryset)
  File "/Users/eugenemekhedov/Documents/TFF/School/apply/admin.py", line 495, in send_certificates
    member
  File "/Users/eugenemekhedov/Documents/TFF/School/apply/admin.py", line 479, in render_to_pdf
    email.send()
  File "/Library/Python/2.7/site-packages/django/core/mail/message.py", line 342, in send
    return self.get_connection(fail_silently).send_messages([self])
  File "/Library/Python/2.7/site-packages/django/core/mail/backends/smtp.py", line 107, in send_messages
    sent = self._send(message)
  File "/Library/Python/2.7/site-packages/django/core/mail/backends/smtp.py", line 121, in _send
    message = email_message.message()
  File "/Library/Python/2.7/site-packages/django/core/mail/message.py", line 306, in message
    msg = self._create_message(msg)
  File "/Library/Python/2.7/site-packages/django/core/mail/message.py", line 394, in _create_message
    return self._create_attachments(msg)
  File "/Library/Python/2.7/site-packages/django/core/mail/message.py", line 407, in _create_attachments
    msg.attach(self._create_attachment(*attachment))
  File "/Library/Python/2.7/site-packages/django/core/mail/message.py", line 449, in _create_attachment
    attachment = self._create_mime_attachment(content, mimetype)
  File "/Library/Python/2.7/site-packages/django/core/mail/message.py", line 437, in _create_mime_attachment
    Encoders.encode_base64(attachment)
  File "/System/Library/Frameworks/Python.framework/Versions/2.7/lib/python2.7/email/encoders.py", line 45, in encode_base64
    encdata = _bencode(orig)
  File "/System/Library/Frameworks/Python.framework/Versions/2.7/lib/python2.7/email/encoders.py", line 31, in _bencode
    hasnewline = (s[-1] == '\n')
TypeError: 'pisaContext' object does not support indexing
Not Found: /accounts/login/
Not Found: /accounts/login/
Not Found: /favicon.ico
Not Found: /favicon.ico
Not Found: /favicon.ico
Not Found: /favicon.ico
Forbidden (CSRF token missing or incorrect.): /admin/login/
Forbidden (CSRF token missing or incorrect.): /admin/login/
Internal Server Error: /reports/
Traceback (most recent call last):
  File "/Library/Python/2.7/site-packages/django/core/handlers/exception.py", line 39, in inner
    response = get_response(request)
  File "/Library/Python/2.7/site-packages/django/core/handlers/base.py", line 249, in _legacy_get_response
    response = self._get_response(request)
  File "/Library/Python/2.7/site-packages/django/core/handlers/base.py", line 187, in _get_response
    response = self.process_exception_by_middleware(e, request)
  File "/Library/Python/2.7/site-packages/channels/handler.py", line 240, in process_exception_by_middleware
    return super(AsgiHandler, self).process_exception_by_middleware(exception, request)
  File "/Library/Python/2.7/site-packages/django/core/handlers/base.py", line 185, in _get_response
    response = wrapped_callback(request, *callback_args, **callback_kwargs)
  File "/Users/eugenemekhedov/Documents/TFF/School/afterSchool/views.py", line 16, in reportList
    return render(request, 'reportList.html', args)
  File "/Library/Python/2.7/site-packages/django/shortcuts.py", line 30, in render
    content = loader.render_to_string(template_name, context, request, using=using)
  File "/Library/Python/2.7/site-packages/django/template/loader.py", line 68, in render_to_string
    return template.render(context, request)
  File "/Library/Python/2.7/site-packages/django/template/backends/django.py", line 66, in render
    return self.template.render(context)
  File "/Library/Python/2.7/site-packages/django/template/base.py", line 208, in render
    return self._render(context)
  File "/Library/Python/2.7/site-packages/django/template/base.py", line 199, in _render
    return self.nodelist.render(context)
  File "/Library/Python/2.7/site-packages/django/template/base.py", line 994, in render
    bit = node.render_annotated(context)
  File "/Library/Python/2.7/site-packages/django/template/base.py", line 961, in render_annotated
    return self.render(context)
  File "/Library/Python/2.7/site-packages/django/template/loader_tags.py", line 174, in render
    return compiled_parent._render(context)
  File "/Library/Python/2.7/site-packages/django/template/base.py", line 199, in _render
    return self.nodelist.render(context)
  File "/Library/Python/2.7/site-packages/django/template/base.py", line 994, in render
    bit = node.render_annotated(context)
  File "/Library/Python/2.7/site-packages/django/template/base.py", line 961, in render_annotated
    return self.render(context)
  File "/Library/Python/2.7/site-packages/django/template/loader_tags.py", line 70, in render
    result = block.nodelist.render(context)
  File "/Library/Python/2.7/site-packages/django/template/base.py", line 994, in render
    bit = node.render_annotated(context)
  File "/Library/Python/2.7/site-packages/django/template/base.py", line 961, in render_annotated
    return self.render(context)
  File "/Library/Python/2.7/site-packages/django/template/defaulttags.py", line 217, in render
    nodelist.append(node.render_annotated(context))
  File "/Library/Python/2.7/site-packages/django/template/base.py", line 961, in render_annotated
    return self.render(context)
  File "/Library/Python/2.7/site-packages/django/template/base.py", line 1044, in render
    output = self.filter_expression.resolve(context)
  File "/Library/Python/2.7/site-packages/django/template/base.py", line 711, in resolve
    obj = self.var.resolve(context)
  File "/Library/Python/2.7/site-packages/django/template/base.py", line 852, in resolve
    value = self._resolve_lookup(context)
  File "/Library/Python/2.7/site-packages/django/template/base.py", line 893, in _resolve_lookup
    current = getattr(current, bit)
  File "/Library/Python/2.7/site-packages/django/db/models/fields/files.py", line 68, in _get_url
    self._require_file()
  File "/Library/Python/2.7/site-packages/django/db/models/fields/files.py", line 46, in _require_file
    raise ValueError("The '%s' attribute has no file associated with it." % self.field.name)
ValueError: The 'image' attribute has no file associated with it.
Internal Server Error: /reports/
Traceback (most recent call last):
  File "/Library/Python/2.7/site-packages/django/core/handlers/exception.py", line 39, in inner
    response = get_response(request)
  File "/Library/Python/2.7/site-packages/django/core/handlers/base.py", line 249, in _legacy_get_response
    response = self._get_response(request)
  File "/Library/Python/2.7/site-packages/django/core/handlers/base.py", line 187, in _get_response
    response = self.process_exception_by_middleware(e, request)
  File "/Library/Python/2.7/site-packages/channels/handler.py", line 240, in process_exception_by_middleware
    return super(AsgiHandler, self).process_exception_by_middleware(exception, request)
  File "/Library/Python/2.7/site-packages/django/core/handlers/base.py", line 185, in _get_response
    response = wrapped_callback(request, *callback_args, **callback_kwargs)
  File "/Users/eugenemekhedov/Documents/TFF/School/afterSchool/views.py", line 16, in reportList
    return render(request, 'reportList.html', args)
  File "/Library/Python/2.7/site-packages/django/shortcuts.py", line 30, in render
    content = loader.render_to_string(template_name, context, request, using=using)
  File "/Library/Python/2.7/site-packages/django/template/loader.py", line 68, in render_to_string
    return template.render(context, request)
  File "/Library/Python/2.7/site-packages/django/template/backends/django.py", line 66, in render
    return self.template.render(context)
  File "/Library/Python/2.7/site-packages/django/template/base.py", line 208, in render
    return self._render(context)
  File "/Library/Python/2.7/site-packages/django/template/base.py", line 199, in _render
    return self.nodelist.render(context)
  File "/Library/Python/2.7/site-packages/django/template/base.py", line 994, in render
    bit = node.render_annotated(context)
  File "/Library/Python/2.7/site-packages/django/template/base.py", line 961, in render_annotated
    return self.render(context)
  File "/Library/Python/2.7/site-packages/django/template/loader_tags.py", line 174, in render
    return compiled_parent._render(context)
  File "/Library/Python/2.7/site-packages/django/template/base.py", line 199, in _render
    return self.nodelist.render(context)
  File "/Library/Python/2.7/site-packages/django/template/base.py", line 994, in render
    bit = node.render_annotated(context)
  File "/Library/Python/2.7/site-packages/django/template/base.py", line 961, in render_annotated
    return self.render(context)
  File "/Library/Python/2.7/site-packages/django/template/loader_tags.py", line 70, in render
    result = block.nodelist.render(context)
  File "/Library/Python/2.7/site-packages/django/template/base.py", line 994, in render
    bit = node.render_annotated(context)
  File "/Library/Python/2.7/site-packages/django/template/base.py", line 961, in render_annotated
    return self.render(context)
  File "/Library/Python/2.7/site-packages/django/template/defaulttags.py", line 217, in render
    nodelist.append(node.render_annotated(context))
  File "/Library/Python/2.7/site-packages/django/template/base.py", line 961, in render_annotated
    return self.render(context)
  File "/Library/Python/2.7/site-packages/django/template/base.py", line 1044, in render
    output = self.filter_expression.resolve(context)
  File "/Library/Python/2.7/site-packages/django/template/base.py", line 711, in resolve
    obj = self.var.resolve(context)
  File "/Library/Python/2.7/site-packages/django/template/base.py", line 852, in resolve
    value = self._resolve_lookup(context)
  File "/Library/Python/2.7/site-packages/django/template/base.py", line 893, in _resolve_lookup
    current = getattr(current, bit)
  File "/Library/Python/2.7/site-packages/django/db/models/fields/files.py", line 68, in _get_url
    self._require_file()
  File "/Library/Python/2.7/site-packages/django/db/models/fields/files.py", line 46, in _require_file
    raise ValueError("The '%s' attribute has no file associated with it." % self.field.name)
ValueError: The 'image' attribute has no file associated with it.
